Workbook

Sheet Resumo mensal
A1: RESUMO MENSAL — quantidade de criativos por empreendimento
A2: Calculado a partir da aba Calendário (se incluir ou remover linhas lá, os números aqui se atualizam).
A4: Empreendimento | B4: OUTUBRO | F4: NOVEMBRO | J4: DEZEMBRO | N4: TOTAL TRIMESTRE
B5: Apresentação: principal argumento de cada projeto | F5: Aprofundamento: produto, condição e prova | J5: Fim de ano: oferta, urgência e 'comece 2027' | N5: Out + Nov + Dez
B6: Vídeos | C6: Carrosséis | D6: Estáticos | E6: Total | F6: Vídeos | G6: Carrosséis | H6: Estáticos | I6: Total | J6: Vídeos | K6: Carrosséis | L6: Estáticos | M6: Total | N6: Vídeos | O6: Carrosséis | P6: Estáticos | Q6: Total
A7: Residencial Mont'Santo | B7: =COUNTIFS(Calendário!$F:$F,$A7,Calendário!$B:$B,"Outubro",Calendário!$G:$G,"Vídeo") -> 2 | C7: =COUNTIFS(Calendário!$F:$F,$A7,Calendário!$B:$B,"Outubro",Calendário!$G:$G,"Carrossel") -> 2 | D7: =COUNTIFS(Calendário!$F:$F,$A7,Calendário!$B:$B,"Outubro",Calendário!$G:$G,"Estático") -> 2 | E7: =SUM(B7:D7) -> 6 | F7: =COUNTIFS(Calendário!$F:$F,$A7,Calendário!$B:$B,"Novembro",Calendário!$G:$G,"Vídeo") -> 2 | G7: =COUNTIFS(Calendário!$F:$F,$A7,Calendário!$B:$B,"Novembro",Calendário!$G:$G,"Carrossel") -> 2 | H7: =COUNTIFS(Calendário!$F:$F,$A7,Calendário!$B:$B,"Novembro",Calendário!$G:$G,"Estático") -> 1 | I7: =SUM(F7:H7) -> 5 | J7: =COUNTIFS(Calendário!$F:$F,$A7,Calendário!$B:$B,"Dezembro",Calendário!$G:$G,"Vídeo") -> 2 | K7: =COUNTIFS(Calendário!$F:$F,$A7,Calendário!$B:$B,"Dezembro",Calendário!$G:$G,"Carrossel") -> 2 | L7: =COUNTIFS(Calendário!$F:$F,$A7,Calendário!$B:$B,"Dezembro",Calendário!$G:$G,"Estático") -> 2 | M7: =SUM(J7:L7) -> 6 | N7: =B7+F7+J7 -> 6 | O7: =C7+G7+K7 -> 6 | P7: =D7+H7+L7 -> 5 | Q7: =SUM(N7:P7) -> 17
A8: Sync Floriano | B8: =COUNTIFS(Calendário!$F:$F,$A8,Calendário!$B:$B,"Outubro",Calendário!$G:$G,"Vídeo") -> 2 | C8: =COUNTIFS(Calendário!$F:$F,$A8,Calendário!$B:$B,"Outubro",Calendário!$G:$G,"Carrossel") -> 2 | D8: =COUNTIFS(Calendário!$F:$F,$A8,Calendário!$B:$B,"Outubro",Calendário!$G:$G,"Estático") -> 2 | E8: =SUM(B8:D8) -> 6 | F8: =COUNTIFS(Calendário!$F:$F,$A8,Calendário!$B:$B,"Novembro",Calendário!$G:$G,"Vídeo") -> 2 | G8: =COUNTIFS(Calendário!$F:$F,$A8,Calendário!$B:$B,"Novembro",Calendário!$G:$G,"Carrossel") -> 2 | H8: =COUNTIFS(Calendário!$F:$F,$A8,Calendário!$B:$B,"Novembro",Calendário!$G:$G,"Estático") -> 1 | I8: =SUM(F8:H8) -> 5 | J8: =COUNTIFS(Calendário!$F:$F,$A8,Calendário!$B:$B,"Dezembro",Calendário!$G:$G,"Vídeo") -> 2 | K8: =COUNTIFS(Calendário!$F:$F,$A8,Calendário!$B:$B,"Dezembro",Calendário!$G:$G,"Carrossel") -> 2 | L8: =COUNTIFS(Calendário!$F:$F,$A8,Calendário!$B:$B,"Dezembro",Calendário!$G:$G,"Estático") -> 2 | M8: =SUM(J8:L8) -> 6 | N8: =B8+F8+J8 -> 6 | O8: =C8+G8+K8 -> 6 | P8: =D8+H8+L8 -> 5 | Q8: =SUM(N8:P8) -> 17
A9: Residencial Einstein | B9: =COUNTIFS(Calendário!$F:$F,$A9,Calendário!$B:$B,"Outubro",Calendário!$G:$G,"Vídeo") -> 2 | C9: =COUNTIFS(Calendário!$F:$F,$A9,Calendário!$B:$B,"Outubro",Calendário!$G:$G,"Carrossel") -> 2 | D9: =COUNTIFS(Calendário!$F:$F,$A9,Calendário!$B:$B,"Outubro",Calendário!$G:$G,"Estático") -> 2 | E9: =SUM(B9:D9) -> 6 | F9: =COUNTIFS(Calendário!$F:$F,$A9,Calendário!$B:$B,"Novembro",Calendário!$G:$G,"Vídeo") -> 2 | G9: =COUNTIFS(Calendário!$F:$F,$A9,Calendário!$B:$B,"Novembro",Calendário!$G:$G,"Carrossel") -> 2 | H9: =COUNTIFS(Calendário!$F:$F,$A9,Calendário!$B:$B,"Novembro",Calendário!$G:$G,"Estático") -> 1 | I9: =SUM(F9:H9) -> 5 | J9: =COUNTIFS(Calendário!$F:$F,$A9,Calendário!$B:$B,"Dezembro",Calendário!$G:$G,"Vídeo") -> 2 | K9: =COUNTIFS(Calendário!$F:$F,$A9,Calendário!$B:$B,"Dezembro",Calendário!$G:$G,"Carrossel") -> 2 | L9: =COUNTIFS(Calendário!$F:$F,$A9,Calendário!$B:$B,"Dezembro",Calendário!$G:$G,"Estático") -> 2 | M9: =SUM(J9:L9) -> 6 | N9: =B9+F9+J9 -> 6 | O9: =C9+G9+K9 -> 6 | P9: =D9+H9+L9 -> 5 | Q9: =SUM(N9:P9) -> 17
A10: Infinity Residence | B10: =COUNTIFS(Calendário!$F:$F,$A10,Calendário!$B:$B,"Outubro",Calendário!$G:$G,"Vídeo") -> 2 | C10: =COUNTIFS(Calendário!$F:$F,$A10,Calendário!$B:$B,"Outubro",Calendário!$G:$G,"Carrossel") -> 2 | D10: =COUNTIFS(Calendário!$F:$F,$A10,Calendário!$B:$B,"Outubro",Calendário!$G:$G,"Estático") -> 2 | E10: =SUM(B10:D10) -> 6 | F10: =COUNTIFS(Calendário!$F:$F,$A10,Calendário!$B:$B,"Novembro",Calendário!$G:$G,"Vídeo") -> 2 | G10: =COUNTIFS(Calendário!$F:$F,$A10,Calendário!$B:$B,"Novembro",Calendário!$G:$G,"Carrossel") -> 2 | H10: =COUNTIFS(Calendário!$F:$F,$A10,Calendário!$B:$B,"Novembro",Calendário!$G:$G,"Estático") -> 1 | I10: =SUM(F10:H10) -> 5 | J10: =COUNTIFS(Calendário!$F:$F,$A10,Calendário!$B:$B,"Dezembro",Calendário!$G:$G,"Vídeo") -> 2 | K10: =COUNTIFS(Calendário!$F:$F,$A10,Calendário!$B:$B,"Dezembro",Calendário!$G:$G,"Carrossel") -> 2 | L10: =COUNTIFS(Calendário!$F:$F,$A10,Calendário!$B:$B,"Dezembro",Calendário!$G:$G,"Estático") -> 2 | M10: =SUM(J10:L10) -> 6 | N10: =B10+F10+J10 -> 6 | O10: =C10+G10+K10 -> 6 | P10: =D10+H10+L10 -> 5 | Q10: =SUM(N10:P10) -> 17
A11: Residencial Amália | B11: =COUNTIFS(Calendário!$F:$F,$A11,Calendário!$B:$B,"Outubro",Calendário!$G:$G,"Vídeo") -> 2 | C11: =COUNTIFS(Calendário!$F:$F,$A11,Calendário!$B:$B,"Outubro",Calendário!$G:$G,"Carrossel") -> 2 | D11: =COUNTIFS(Calendário!$F:$F,$A11,Calendário!$B:$B,"Outubro",Calendário!$G:$G,"Estático") -> 2 | E11: =SUM(B11:D11) -> 6 | F11: =COUNTIFS(Calendário!$F:$F,$A11,Calendário!$B:$B,"Novembro",Calendário!$G:$G,"Vídeo") -> 2 | G11: =COUNTIFS(Calendário!$F:$F,$A11,Calendário!$B:$B,"Novembro",Calendário!$G:$G,"Carrossel") -> 2 | H11: =COUNTIFS(Calendário!$F:$F,$A11,Calendário!$B:$B,"Novembro",Calendário!$G:$G,"Estático") -> 1 | I11: =SUM(F11:H11) -> 5 | J11: =COUNTIFS(Calendário!$F:$F,$A11,Calendário!$B:$B,"Dezembro",Calendário!$G:$G,"Vídeo") -> 2 | K11: =COUNTIFS(Calendário!$F:$F,$A11,Calendário!$B:$B,"Dezembro",Calendário!$G:$G,"Carrossel") -> 2 | L11: =COUNTIFS(Calendário!$F:$F,$A11,Calendário!$B:$B,"Dezembro",Calendário!$G:$G,"Estático") -> 2 | M11: =SUM(J11:L11) -> 6 | N11: =B11+F11+J11 -> 6 | O11: =C11+G11+K11 -> 6 | P11: =D11+H11+L11 -> 5 | Q11: =SUM(N11:P11) -> 17
A12: Residencial Fiorello | B12: =COUNTIFS(Calendário!$F:$F,$A12,Calendário!$B:$B,"Outubro",Calendário!$G:$G,"Vídeo") -> 2 | C12: =COUNTIFS(Calendário!$F:$F,$A12,Calendário!$B:$B,"Outubro",Calendário!$G:$G,"Carrossel") -> 2 | D12: =COUNTIFS(Calendário!$F:$F,$A12,Calendário!$B:$B,"Outubro",Calendário!$G:$G,"Estático") -> 2 | E12: =SUM(B12:D12) -> 6 | F12: =COUNTIFS(Calendário!$F:$F,$A12,Calendário!$B:$B,"Novembro",Calendário!$G:$G,"Vídeo") -> 2 | G12: =COUNTIFS(Calendário!$F:$F,$A12,Calendário!$B:$B,"Novembro",Calendário!$G:$G,"Carrossel") -> 2 | H12: =COUNTIFS(Calendário!$F:$F,$A12,Calendário!$B:$B,"Novembro",Calendário!$G:$G,"Estático") -> 1 | I12: =SUM(F12:H12) -> 5 | J12: =COUNTIFS(Calendário!$F:$F,$A12,Calendário!$B:$B,"Dezembro",Calendário!$G:$G,"Vídeo") -> 2 | K12: =COUNTIFS(Calendário!$F:$F,$A12,Calendário!$B:$B,"Dezembro",Calendário!$G:$G,"Carrossel") -> 2 | L12: =COUNTIFS(Calendário!$F:$F,$A12,Calendário!$B:$B,"Dezembro",Calendário!$G:$G,"Estático") -> 2 | M12: =SUM(J12:L12) -> 6 | N12: =B12+F12+J12 -> 6 | O12: =C12+G12+K12 -> 6 | P12: =D12+H12+L12 -> 5 | Q12: =SUM(N12:P12) -> 17
A13: Primado Residence | B13: =COUNTIFS(Calendário!$F:$F,$A13,Calendário!$B:$B,"Outubro",Calendário!$G:$G,"Vídeo") -> 2 | C13: =COUNTIFS(Calendário!$F:$F,$A13,Calendário!$B:$B,"Outubro",Calendário!$G:$G,"Carrossel") -> 2 | D13: =COUNTIFS(Calendário!$F:$F,$A13,Calendário!$B:$B,"Outubro",Calendário!$G:$G,"Estático") -> 2 | E13: =SUM(B13:D13) -> 6 | F13: =COUNTIFS(Calendário!$F:$F,$A13,Calendário!$B:$B,"Novembro",Calendário!$G:$G,"Vídeo") -> 2 | G13: =COUNTIFS(Calendário!$F:$F,$A13,Calendário!$B:$B,"Novembro",Calendário!$G:$G,"Carrossel") -> 2 | H13: =COUNTIFS(Calendário!$F:$F,$A13,Calendário!$B:$B,"Novembro",Calendário!$G:$G,"Estático") -> 1 | I13: =SUM(F13:H13) -> 5 | J13: =COUNTIFS(Calendário!$F:$F,$A13,Calendário!$B:$B,"Dezembro",Calendário!$G:$G,"Vídeo") -> 2 | K13: =COUNTIFS(Calendário!$F:$F,$A13,Calendário!$B:$B,"Dezembro",Calendário!$G:$G,"Carrossel") -> 2 | L13: =COUNTIFS(Calendário!$F:$F,$A13,Calendário!$B:$B,"Dezembro",Calendário!$G:$G,"Estático") -> 2 | M13: =SUM(J13:L13) -> 6 | N13: =B13+F13+J13 -> 6 | O13: =C13+G13+K13 -> 6 | P13: =D13+H13+L13 -> 5 | Q13: =SUM(N13:P13) -> 17
A14: Moradas do Lago | B14: =COUNTIFS(Calendário!$F:$F,$A14,Calendário!$B:$B,"Outubro",Calendário!$G:$G,"Vídeo") -> 2 | C14: =COUNTIFS(Calendário!$F:$F,$A14,Calendário!$B:$B,"Outubro",Calendário!$G:$G,"Carrossel") -> 2 | D14: =COUNTIFS(Calendário!$F:$F,$A14,Calendário!$B:$B,"Outubro",Calendário!$G:$G,"Estático") -> 2 | E14: =SUM(B14:D14) -> 6 | F14: =COUNTIFS(Calendário!$F:$F,$A14,Calendário!$B:$B,"Novembro",Calendário!$G:$G,"Vídeo") -> 2 | G14: =COUNTIFS(Calendário!$F:$F,$A14,Calendário!$B:$B,"Novembro",Calendário!$G:$G,"Carrossel") -> 2 | H14: =COUNTIFS(Calendário!$F:$F,$A14,Calendário!$B:$B,"Novembro",Calendário!$G:$G,"Estático") -> 1 | I14: =SUM(F14:H14) -> 5 | J14: =COUNTIFS(Calendário!$F:$F,$A14,Calendário!$B:$B,"Dezembro",Calendário!$G:$G,"Vídeo") -> 2 | K14: =COUNTIFS(Calendário!$F:$F,$A14,Calendário!$B:$B,"Dezembro",Calendário!$G:$G,"Carrossel") -> 2 | L14: =COUNTIFS(Calendário!$F:$F,$A14,Calendário!$B:$B,"Dezembro",Calendário!$G:$G,"Estático") -> 2 | M14: =SUM(J14:L14) -> 6 | N14: =B14+F14+J14 -> 6 | O14: =C14+G14+K14 -> 6 | P14: =D14+H14+L14 -> 5 | Q14: =SUM(N14:P14) -> 17
A15: TOTAL GO | B15: =SUM(B7:B14) -> 16 | C15: =SUM(C7:C14) -> 16 | D15: =SUM(D7:D14) -> 16 | E15: =SUM(E7:E14) -> 48 | F15: =SUM(F7:F14) -> 16 | G15: =SUM(G7:G14) -> 16 | H15: =SUM(H7:H14) -> 8 | I15: =SUM(I7:I14) -> 40 | ... Q15: =SUM(Q7:Q14) -> 136

Sheet Calendário
A1: CALENDÁRIO DE CRIATIVOS — TRÁFEGO PAGO | OUT a DEZ/2026
A2: GoCompany · 136 criativos novos · 2 vídeos por projeto/mês · cada empreendimento tem um dia fixo de subida (Ter, Qua, Qui ou Sex) para manter o fluxo leve e constante
A4: Nº | B4: Mês | C4: Semana | D4: Data no ar | E4: Dia | F4: Empreendimento | G4: Formato | H4: Tema | I4: Ideia do criativo | J4: Chamada principal | K4: CTA | L4: Aprovação até | M4: Status | N4: Responsável | O4: Observações
A5: 1 | B5: Outubro | C5: S01 · 12/10–16/10 | D5: 46308 | E5: =CHOOSE(WEEKDAY(D5),"Dom","Seg","Ter","Qua","Qui","Sex","Sáb") -> Ter | F5: Residencial Mont'Santo | G5: Vídeo | H5: Preço de custo | I5: Consultor na obra explica em 30s o que é obra a preço de custo e por que o m² sai abaixo do alto padrão da cidade. | J5: O m² mais em conta de Santa Maria no verdadeiro alto padrão. | K5: Fale com um consultor no WhatsApp | L5: =WORKDAY(D5,-Premissas!$B$4,Premissas!$E$5:$E$11) -> 46303 | M5: A produzir
A6: 2 | B6: Outubro | C6: S01 · 12/10–16/10 | D6: 46308 | E6: =CHOOSE(WEEKDAY(D6),"Dom","Seg","Ter","Qua","Qui","Sex","Sáb") -> Ter | F6: Residencial Mont'Santo | G6: Estático | H6: Preço do m² | I6: Fachada/render + frase de impacto. | J6: O m² mais em conta da cidade no verdadeiro alto padrão. | K6: Fale com um consultor no WhatsApp | L6: =WORKDAY(D6,-Premissas!$B$4,Premissas!$E$5:$E$11) -> 46303 | M6: A produzir
A7: 3 | B7: Outubro | C7: S01 · 12/10–16/10 | D7: 46308 | E7: =CHOOSE(WEEKDAY(D7),"Dom","Seg","Ter","Qua","Qui","Sex","Sáb") -> Ter | F7: Sync Floriano | G7: Carrossel | H7: Condição passo a passo | I7: Card 1 entrada, card 2 parcelas, card 3 prazo de 40 meses, card 4 'monte a sua condição'. | J7: Do jeito que cabe no seu bolso. | K7: Simule sua condição no WhatsApp | L7: =WORKDAY(D7,-Premissas!$B$4,Premissas!$E$5:$E$11) -> 46303 | M7: A produzir | O7: Validar valores da condição com a construtora
A8: 4 | B8: Outubro | C8: S01 · 12/10–16/10 | D8: 46308 | E8: =CHOOSE(WEEKDAY(D8),"Dom","Seg","Ter","Qua","Qui","Sex","Sáb") -> Ter | F8: Sync Floriano | G8: Estático | H8: Entrada | I8: Render + números grandes. | J8: Entrada de R$ 10 mil + 40 meses para pagar. | K8: Simule sua condição no WhatsApp | L8: =WORKDAY(D8,-Premissas!$B$4,Premissas!$E$5:$E$11) -> 46303 | M8: A produzir | O8: Validar valores da condição com a construtora
A9: 5 | B9: Outubro | C9: S01 · 12/10–16/10 | D9: 46309 | E9: =CHOOSE(WEEKDAY(D9),"Dom","Seg","Ter","Qua","Qui","Sex","Sáb") -> Qua | F9: Residencial Einstein | G9: Vídeo | H9: Quase pronto | I9: Tour pela obra em fase final (acabamentos, fachada, áreas comuns). | J9: Falta pouco para você pegar as chaves. | K9: Fale com um consultor no WhatsApp | L9: =WORKDAY(D9,-Premissas!$B$4,Premissas!$E$5:$E$11) -> 46304 | M9: A produzir
A10: 6 | B10: Outubro | C10: S01 · 12/10–16/10 | D10: 46309 | E10: =CHOOSE(WEEKDAY(D10),"Dom","Seg","Ter","Qua","Qui","Sex","Sáb") -> Qua | F10: Residencial Einstein | G10: Estático | H10: Condição | I10: Render + números destacados. | J10: 20% durante a obra. Saldo nas chaves. | K10: Fale com um consultor no WhatsApp | L10: =WORKDAY(D10,-Premissas!$B$4,Premissas!$E$5:$E$11) -> 46304 | M10: A produzir
A11: 7 | B11: Outubro | C11: S01 · 12/10–16/10 | D11: 46309 | E11: =CHOOSE(WEEKDAY(D11),"Dom","Seg","Ter","Qua","Qui","Sex","Sáb") -> Qua | F11: Infinity Residence | G11: Vídeo | H11: Manifesto | I11: Vídeo cinematográfico, sem preço: arquitetura, luz, texturas e trilha sofisticada. | J11: Poucos endereços são únicos. Este é um deles. | K11: Agende uma apresentação privada | L11: =WORKDAY(D11,-Premissas!$B$4,Premissas!$E$5:$E$11) -> 46304 | M11: A produzir
A12: 8 | B12: Outubro | C12: S01 · 12/10–16/10 | D12: 46309 | E12: =CHOOSE(WEEKDAY(D12),"Dom","Seg","Ter","Qua","Qui","Sex","Sáb") -> Qua | F12: Infinity Residence | G12: Estático | H12: Exclusividade | I12: Render principal, layout minimalista. | J12: Exclusividade não se repete. | K12: Agende uma apresentação privada | L12: =WORKDAY(D12,-Premissas!$B$4,Premissas!$E$5:$E$11) -> 46304 | M12: A produzir
A13: 9 | B13: Outubro | C13: S01 · 12/10–16/10 | D13: 46310 | E13: =CHOOSE(WEEKDAY(D13),"Dom","Seg","Ter","Qua","Qui","Sex","Sáb") -> Qui | F13: Residencial Amália | G13: Carrossel | H13: Por que perto da UFSM | I13: Vantagens de morar perto da universidade (tempo, segurança, rotina). | J13: Morar perto da UFSM muda a rotina. | K13: Fale com um consultor no WhatsApp | L13: =WORKDAY(D13,-Premissas!$B$4,Premissas!$E$5:$E$11) -> 46308 | M13: A produzir
A14: 10 | B14: Outubro | C14: S01 · 12/10–16/10 | D14: 46310 | E14: =CHOOSE(WEEKDAY(D14),"Dom","Seg","Ter","Qua","Qui","Sex","Sáb") -> Qui | F14: Residencial Amália | G14: Estático | H14: Localização | I14: Render + pin UFSM. | J14: Do lado da UFSM. | K14: Fale com um consultor no WhatsApp | L14: =WORKDAY(D14,-Premissas!$B$4,Premissas!$E$5:$E$11) -> 46308 | M14: A produzir
A15: 11 | B15: Outubro | C15: S01 · 12/10–16/10 | D15: 46310 | E15: =CHOOSE(WEEKDAY(D15),"Dom","Seg","Ter","Qua","Qui","Sex","Sáb") -> Qui | F15: Residencial Fiorello | G15: Vídeo | H15: Últimas unidades | I15: Tour pelos 2 apartamentos tipo disponíveis e pela cobertura. | J15: 2 apartamentos tipo e a cobertura: as últimas oportunidades do Fiorello. | K15: Agende sua visita | L15: =WORKDAY(D15,-Premissas!$B$4,Premissas!$E$5:$E$11) -> 46308 | M15: A produzir | O15: Pausar/atualizar se alguma unidade for vendida
A16: 12 | B16: Outubro | C16: S01 · 12/10–16/10 | D16: 46310 | E16: =CHOOSE(WEEKDAY(D16),"Dom","Seg","Ter","Qua","Qui","Sex","Sáb") -> Qui | F16: Residencial Fiorello | G16: Estático | H16: Urgência | I16: Foto + selo 'últimas unidades'. | J16: Últimas unidades: 2 apartamentos tipo e a cobertura. | K16: Agende sua visita | L16: =WORKDAY(D16,-Premissas!$B$4,Premissas!$E$5:$E$11) -> 46308 | M16: A produzir | O16: Pausar/atualizar se alguma unidade for vendida
A17: 13 | B17: Outubro | C17: S01 · 12/10–16/10 | D17: 46311 | E17: =CHOOSE(WEEKDAY(D17),"Dom","Seg","Ter","Qua","Qui","Sex","Sáb") -> Sex | F17: Primado Residence | G17: Vídeo | H17: 7 min do Recanto Maestro | I17: Trajeto de carro do loteamento até o Recanto Maestro com cronômetro na tela. | J17: A 7 minutos do Recanto Maestro. | K17: Fale com um consultor no WhatsApp | L17: =WORKDAY(D17,-Premissas!$B$4,Premissas!$E$5:$E$11) -> 46309 | M17: A produzir
A18: 14 | B18: Outubro | C18: S01 · 12/10–16/10 | D18: 46311 | E18: =CHOOSE(WEEKDAY(D18),"Dom","Seg","Ter","Qua","Qui","Sex","Sáb") -> Sex | F18: Primado Residence | G18: Estático | H18: Localização | I18: Foto aérea + selo de distância. | J18: A 7 minutos do Recanto Maestro. | K18: Fale com um consultor no WhatsApp | L18: =WORKDAY(D18,-Premissas!$B$4,Premissas!$E$5:$E$11) -> 46309 | M18: A produzir
A19: 15 | B19: Outubro | C19: S01 · 12/10–16/10 | D19: 46311 | E19: =CHOOSE(WEEKDAY(D19),"Dom","Seg","Ter","Qua","Qui","Sex","Sáb") -> Sex | F19: Moradas do Lago | G19: Carrossel | H19: 3 jeitos de comprar | I19: Card financiamento Banrisul, card direto, card permuta. | J19: 3 jeitos de comprar o seu apê. | K19: Simule seu financiamento no WhatsApp | L19: =WORKDAY(D19,-Premissas!$B$4,Premissas!$E$5:$E$11) -> 46309 | M19: A produzir
A20: 16 | B20: Outubro | C20: S01 · 12/10–16/10 | D20: 46311 | E20: =CHOOSE(WEEKDAY(D20),"Dom","Seg","Ter","Qua","Qui","Sex","Sáb") -> Sex | F20: Moradas do Lago | G20: Estático | H20: Pronto | I20: Foto da fachada. | J20: Pronto para morar em Lajeado. | K20: Simule seu financiamento no WhatsApp | L20: =WORKDAY(D20,-Premissas!$B$4,Premissas!$E$5:$E$11) -> 46309 | M20: A produzir
A21: 17 | B21: Outubro | C21: S02 · 19/10–23/10 | D21: 46315 | E21: =CHOOSE(WEEKDAY(D21),"Dom","Seg","Ter","Qua","Qui","Sex","Sáb") -> Ter | F21: Residencial Mont'Santo | G21: Vídeo | H21: Localização premium | I21: Imagens de drone da Av. Medianeira e do entorno (comércio, serviços, acessos) chegando até o empreendimento. | J21: Morar na Medianeira, com o padrão que você sempre quis. | K21: Fale com um consultor no WhatsApp | L21: =WORKDAY(D21,-Premissas!$B$4,Premissas!$E$5:$E$11) -> 46311 | M21: A produzir
A22: 18 | B22: Outubro | C22: S02 · 19/10–23/10 | D22: 46315 | E22: =CHOOSE(WEEKDAY(D22),"Dom","Seg","Ter","Qua","Qui","Sex","Sáb") -> Ter | F22: Residencial Mont'Santo | G22: Carrossel | H22: 5 motivos | I22: Card por argumento: preço de custo, Av. Medianeira, 124–245 m², padrão de acabamento, entrega em 20 meses. | J22: 5 motivos para escolher o Mont'Santo. | K22: Fale com um consultor no WhatsApp | L22: =WORKDAY(D22,-Premissas!$B$4,Premissas!$E$5:$E$11) -> 46311 | M22: A produzir
A23: 19 | B23: Outubro | C23: S02 · 19/10–23/10 | D23: 46315 | E23: =CHOOSE(WEEKDAY(D23),"Dom","Seg","Ter","Qua","Qui","Sex","Sáb") -> Ter | F23: Sync Floriano | G23: Vídeo | H23: Condição facilitada | I23: Consultor mostra na tela: entrada a partir de R$ 10 mil (ou 10%) e saldo em até 40 meses. | J23: Seu apê com entrada de R$ 10 mil e 40 meses para pagar. | K23: Simule sua condição no WhatsApp | L23: =WORKDAY(D23,-Premissas!$B$4,Premissas!$E$5:$E$11) -> 46311 | M23: A produzir | O23: Validar valores da condição com a construtora
A24: 20 | B24: Outubro | C24: S02 · 19/10–23/10 | D24: 46315 | E24: =CHOOSE(WEEKDAY(D24),"Dom","Seg","Ter","Qua","Qui","Sex","Sáb") -> Ter | F24: Sync Floriano | G24: Carrossel | H24: Qual tipologia é a sua | I24: Um card por tipologia com perfil de morador. | J24: Studio, 1 ou 2 dorm: qual é o seu? | K24: Simule sua condição no WhatsApp | L24: =WORKDAY(D24,-Premissas!$B$4,Premissas!$E$5:$E$11) -> 46311 | M24: A produzir
A25: 21 | B25: Outubro | C25: S02 · 19/10–23/10 | D25: 46316 | E25: =CHOOSE(WEEKDAY(D25),"Dom","Seg","Ter","Qua","Qui","Sex","Sáb") -> Qua | F25: Residencial Einstein | G25: Carrossel | H25: Como pagar | I25: 20% durante a obra → saldo financiado nas chaves, em cards simples. | J25: Pague 20% na obra e o saldo só nas chaves. | K25: Fale com um consultor no WhatsApp | L25: =WORKDAY(D25,-Premissas!$B$4,Premissas!$E$5:$E$11) -> 46314 | M25: A produzir
A26: 22 | B26: Outubro | C26: S02 · 19/10–23/10 | D26: 46316 | E26: =CHOOSE(WEEKDAY(D26),"Dom","Seg","Ter","Qua","Qui","Sex","Sáb") -> Qua | F26: Residencial Einstein | G26: Estático | H26: Permuta | I26: Render + selo 'aceita permuta'. | J26: Aceitamos o seu bem como parte do pagamento. | K26: Fale com um consultor no WhatsApp | L26: =WORKDAY(D26,-Premissas!$B$4,Premissas!$E$5:$E$11) -> 46314 | M26: A produzir | O26: Confirmar bens aceitos em permuta
A27: 23 | B27: Outubro | C27: S02 · 19/10–23/10 | D27: 46316 | E27: =CHOOSE(WEEKDAY(D27),"Dom","Seg","Ter","Qua","Qui","Sex","Sáb") -> Qua | F27: Infinity Residence | G27: Vídeo | H27: Localização | I27: Drone revelando o entorno e o skyline com o empreendimento em destaque. | J27: No centro de tudo. Acima de tudo. | K27: Agende uma apresentação privada | L27: =WORKDAY(D27,-Premissas!$B$4,Premissas!$E$5:$E$11) -> 46314 | M27: A produzir
A28: 24 | B28: Outubro | C28: S02 · 19/10–23/10 | D28: 46316 | E28: =CHOOSE(WEEKDAY(D28),"Dom","Seg","Ter","Qua","Qui","Sex","Sáb") -> Qua | F28: Infinity Residence | G28: Carrossel | H28: O que torna único | I28: 5 cards com atributos exclusivos do projeto. | J28: Por que não existe outro Infinity. | K28: Agende uma apresentação privada | L28: =WORKDAY(D28,-Premissas!$B$4,Premissas!$E$5:$E$11) -> 46314 | M28: A produzir
A29: 25 | B29: Outubro | C29: S02 · 19/10–23/10 | D29: 46317 | E29: =CHOOSE(WEEKDAY(D29),"Dom","Seg","Ter","Qua","Qui","Sex","Sáb") -> Qui | F29: Residencial Amália | G29: Vídeo | H29: Perto da UFSM | I29: Trajeto do empreendimento até a UFSM com tempo na tela. | J29: Pertinho da UFSM e pronto para o início do ano. | K29: Fale com um consultor no WhatsApp | L29: =WORKDAY(D29,-Premissas!$B$4,Premissas!$E$5:$E$11) -> 46315 | M29: A produzir
A30: 26 | B30: Outubro | C30: S02 · 19/10–23/10 | D30: 46317 | E30: =CHOOSE(WEEKDAY(D30),"Dom","Seg","Ter","Qua","Qui","Sex","Sáb") -> Qui | F30: Residencial Amália | G30: Carrossel | H30: Comprar x alugar | I30: Comparativo para os pais: aluguel por 5 anos x parcela do imóvel. | J30: Aluguel ou patrimônio? Faça as contas. | K30: Fale com um consultor no WhatsApp | L30: =WORKDAY(D30,-Premissas!$B$4,Premissas!$E$5:$E$11) -> 46315 | M30: A produzir
A31: 27 | B31: Outubro | C31: S02 · 19/10–23/10 | D31: 46317 | E31: =CHOOSE(WEEKDAY(D31),"Dom","Seg","Ter","Qua","Qui","Sex","Sáb") -> Qui | F31: Residencial Fiorello | G31: Carrossel | H31: Unidades disponíveis | I31: Um card para cada apartamento tipo e um para a cobertura, com metragem e destaque. | J31: Conheça as unidades disponíveis, incluindo a cobertura. | K31: Agende sua visita | L31: =WORKDAY(D31,-Premissas!$B$4,Premissas!$E$5:$E$11) -> 46315 | M31: A produzir
A32: 28 | B32: Outubro | C32: S02 · 19/10–23/10 | D32: 46317 | E32: =CHOOSE(WEEKDAY(D32),"Dom","Seg","Ter","Qua","Qui","Sex","Sáb") -> Qui | F32: Residencial Fiorello | G32: Estático | H32: Permuta | I32: Foto + selo de permuta. | J32: Até 50% em permuta. | K32: Agende sua visita | L32: =WORKDAY(D32,-Premissas!$B$4,Premissas!$E$5:$E$11) -> 46315 | M32: A produzir
A33: 29 | B33: Outubro | C33: S02 · 19/10–23/10 | D33: 46318 | E33: =CHOOSE(WEEKDAY(D33),"Dom","Seg","Ter","Qua","Qui","Sex","Sáb") -> Sex | F33: Primado Residence | G33: Vídeo | H33: Infraestrutura pronta | I33: Drone pelas ruas, calçamento e redes já executadas. | J33: Lotes com 95% da infraestrutura concluída. | K33: Fale com um consultor no WhatsApp | L33: =WORKDAY(D33,-Premissas!$B$4,Premissas!$E$5:$E$11) -> 46316 | M33: A produzir
A34: 30 | B34: Outubro | C34: S02 · 19/10–23/10 | D34: 46318 | E34: =CHOOSE(WEEKDAY(D34),"Dom","Seg","Ter","Qua","Qui","Sex","Sáb") -> Sex | F34: Primado Residence | G34: Carrossel | H34: Por que investir | I34: Cards: turismo o ano todo, valorização da região, infraestrutura pronta. | J34: Por que investir perto do Recanto Maestro. | K34: Fale com um consultor no WhatsApp | L34: =WORKDAY(D34,-Premissas!$B$4,Premissas!$E$5:$E$11) -> 46316 | M34: A produzir
A35: 31 | B35: Outubro | C35: S02 · 19/10–23/10 | D35: 46318 | E35: =CHOOSE(WEEKDAY(D35),"Dom","Seg","Ter","Qua","Qui","Sex","Sáb") -> Sex | F35: Moradas do Lago | G35: Vídeo | H35: Pronto para morar | I35: Tour pelo apartamento pronto em Lajeado. | J35: Pronto para morar em Lajeado. | K35: Simule seu financiamento no WhatsApp | L35: =WORKDAY(D35,-Premissas!$B$4,Premissas!$E$5:$E$11) -> 46316 | M35: A produzir
A36: 32 | B36: Outubro | C36: S02 · 19/10–23/10 | D36: 46318 | E36: =CHOOSE(WEEKDAY(D36),"Dom","Seg","Ter","Qua","Qui","Sex","Sáb") -> Sex | F36: Moradas do Lago | G36: Carrossel | H36: Tour fotográfico | I36: Fotos reais, ambiente por ambiente. | J36: Veja o Moradas do Lago por dentro. | K36: Simule seu financiamento no WhatsApp | L36: =WORKDAY(D36,-Premissas!$B$4,Premissas!$E$5:$E$11) -> 46316 | M36: A produzir
A37: 33 | B37: Outubro | C37: S03 · 26/10–30/10 | D37: 46322 | E37: =CHOOSE(WEEKDAY(D37),"Dom","Seg","Ter","Qua","Qui","Sex","Sáb") -> Ter | F37: Residencial Mont'Santo | G37: Carrossel | H37: Como funciona o preço de custo | I37: Passo a passo simples da obra a preço de custo e por que o cliente paga o valor real da construção. | J37: Entenda por que o seu m² custa menos aqui. | K37: Fale com um consultor no WhatsApp | L37: =WORKDAY(D37,-Premissas!$B$4,Premissas!$E$5:$E$11) -> 46318 | M37: A produzir
A38: 34 | B38: Outubro | C38: S03 · 26/10–30/10 | D38: 46322 | E38: =CHOOSE(WEEKDAY(D38),"Dom","Seg","Ter","Qua","Qui","Sex","Sáb") -> Ter | F38: Residencial Mont'Santo | G38: Estático | H38: Localização | I38: Foto aérea da Medianeira com selo do empreendimento. | J38: Avenida Medianeira. Alto padrão. Preço de custo. | K38: Fale com um consultor no WhatsApp | L38: =WORKDAY(D38,-Premissas!$B$4,Premissas!$E$5:$E$11) -> 46318 | M38: A produzir
... A50: 46 | B50: Outubro | C50: S03 · 26/10–30/10 | D50: 46325 | E50: =CHOOSE(WEEKDAY(D50),"Dom","Seg","Ter","Qua","Qui","Sex","Sáb") -> Sex | F50: Primado Residence | G50: Estático | H50: Infraestrutura | I50: Foto das ruas prontas. | J50: Lotes com infraestrutura 95% concluída. | K50: Fale com um consultor no WhatsApp | L50: =WORKDAY(D50,-Premissas!$B$4,Premissas!$E$5:$E$11) -> 46323 | M50: A produzir
A51: 47 | B51: Outubro | C51: S03 · 26/10–30/10 | D51: 46325 | E51: =CHOOSE(WEEKDAY(D51),"Dom","Seg","Ter","Qua","Qui","Sex","Sáb") -> Sex | F51: Moradas do Lago | G51: Vídeo | H51: Financiamento 100% | I51: Consultor explica o financiamento de até 100% pelo Banrisul. | J51: Financiamento de até 100% pelo Banrisul. | K51: Simule seu financiamento no WhatsApp | L51: =WORKDAY(D51,-Premissas!$B$4,Premissas!$E$5:$E$11) -> 46323 | M51: A produzir | O51: Validar uso da marca Banrisul
A52: 48 | B52: Outubro | C52: S03 · 26/10–30/10 | D52: 46325 | E52: =CHOOSE(WEEKDAY(D52),"Dom","Seg","Ter","Qua","Qui","Sex","Sáb") -> Sex | F52: Moradas do Lago | G52: Estático | H52: Financiamento | I52: Foto + selo Banrisul (validar uso da marca). | J52: Financiamento de até 100% pelo Banrisul. | K52: Simule seu financiamento no WhatsApp | L52: =WORKDAY(D52,-Premissas!$B$4,Premissas!$E$5:$E$11) -> 46323 | M52: A produzir | O52: Validar uso da marca Banrisul
...

Sheet Fluxo semanal
A1: FLUXO SEMANAL — peças que sobem por semana
A2: Distribuição pensada para não concentrar produção: ~5 a 6 vídeos por semana na carteira toda. Dias fixos: Ter = Mont'Santo e Sync · Qua = Einstein e Infinity · Qui = Amália e Fiorello · Sex = Primado e Moradas.
A4: Empreendimento | B4: Dia fixo | C4: S01 · 12/10–16/10 | D4: S02 · 19/10–23/10 | E4: S03 · 26/10–30/10 | F4: S04 · 02/11–06/11 | G4: S05 · 09/11–13/11 | H4: S06 · 16/11–20/11 | I4: S07 · 23/11–27/11 | J4: S08 · 30/11–04/12 | K4: S09 · 07/12–11/12 | L4: S10 · 14/12–18/12 | M4: Total
A5: Residencial Mont'Santo | B5: Terça | C5: =COUNTIFS(Calendário!$F:$F,$A5,Calendário!$C:$C,C$4) -> 2 | D5: =COUNTIFS(Calendário!$F:$F,$A5,Calendário!$C:$C,D$4) -> 2 | E5: =COUNTIFS(Calendário!$F:$F,$A5,Calendário!$C:$C,E$4) -> 2 | F5: =COUNTIFS(Calendário!$F:$F,$A5,Calendário!$C:$C,F$4) -> 1 | G5: =COUNTIFS(Calendário!$F:$F,$A5,Calendário!$C:$C,G$4) -> 2 | H5: =COUNTIFS(Calendário!$F:$F,$A5,Calendário!$C:$C,H$4) -> 1 | I5: =COUNTIFS(Calendário!$F:$F,$A5,Calendário!$C:$C,I$4) -> 1 | J5: =COUNTIFS(Calendário!$F:$F,$A5,Calendário!$C:$C,J$4) -> 2 | ... L5: =COUNTIFS(Calendário!$F:$F,$A5,Calendário!$C:$C,L$4) -> 2 | M5: =SUM(C5:L5) -> 17
A6: Sync Floriano | B6: Terça | C6: =COUNTIFS(Calendário!$F:$F,$A6,Calendário!$C:$C,C$4) -> 2 | D6: =COUNTIFS(Calendário!$F:$F,$A6,Calendário!$C:$C,D$4) -> 2 | E6: =COUNTIFS(Calendário!$F:$F,$A6,Calendário!$C:$C,E$4) -> 2 | F6: =COUNTIFS(Calendário!$F:$F,$A6,Calendário!$C:$C,F$4) -> 1 | G6: =COUNTIFS(Calendário!$F:$F,$A6,Calendário!$C:$C,G$4) -> 2 | H6: =COUNTIFS(Calendário!$F:$F,$A6,Calendário!$C:$C,H$4) -> 1 | I6: =COUNTIFS(Calendário!$F:$F,$A6,Calendário!$C:$C,I$4) -> 1 | J6: =COUNTIFS(Calendário!$F:$F,$A6,Calendário!$C:$C,J$4) -> 2 | ... L6: =COUNTIFS(Calendário!$F:$F,$A6,Calendário!$C:$C,L$4) -> 2 | M6: =SUM(C6:L6) -> 17
A7: Residencial Einstein | B7: Quarta | C7: =COUNTIFS(Calendário!$F:$F,$A7,Calendário!$C:$C,C$4) -> 2 | D7: =COUNTIFS(Calendário!$F:$F,$A7,Calendário!$C:$C,D$4) -> 2 | E7: =COUNTIFS(Calendário!$F:$F,$A7,Calendário!$C:$C,E$4) -> 2 | F7: =COUNTIFS(Calendário!$F:$F,$A7,Calendário!$C:$C,F$4) -> 1 | G7: =COUNTIFS(Calendário!$F:$F,$A7,Calendário!$C:$C,G$4) -> 2 | H7: =COUNTIFS(Calendário!$F:$F,$A7,Calendário!$C:$C,H$4) -> 1 | I7: =COUNTIFS(Calendário!$F:$F,$A7,Calendário!$C:$C,I$4) -> 1 | J7: =COUNTIFS(Calendário!$F:$F,$A7,Calendário!$C:$C,J$4) -> 2 | ... L7: =COUNTIFS(Calendário!$F:$F,$A7,Calendário!$C:$C,L$4) -> 2 | M7: =SUM(C7:L7) -> 17
A8: Infinity Residence | B8: Quarta | C8: =COUNTIFS(Calendário!$F:$F,$A8,Calendário!$C:$C,C$4) -> 2 | D8: =COUNTIFS(Calendário!$F:$F,$A8,Calendário!$C:$C,D$4) -> 2 | E8: =COUNTIFS(Calendário!$F:$F,$A8,Calendário!$C:$C,E$4) -> 2 | F8: =COUNTIFS(Calendário!$F:$F,$A8,Calendário!$C:$C,F$4) -> 1 | G8: =COUNTIFS(Calendário!$F:$F,$A8,Calendário!$C:$C,G$4) -> 2 | H8: =COUNTIFS(Calendário!$F:$F,$A8,Calendário!$C:$C,H$4) -> 1 | I8: =COUNTIFS(Calendário!$F:$F,$A8,Calendário!$C:$C,I$4) -> 1 | J8: =COUNTIFS(Calendário!$F:$F,$A8,Calendário!$C:$C,J$4) -> 2 | ... L8: =COUNTIFS(Calendário!$F:$F,$A8,Calendário!$C:$C,L$4) -> 2 | M8: =SUM(C8:L8) -> 17
A9: Residencial Amália | B9: Quinta | C9: =COUNTIFS(Calendário!$F:$F,$A9,Calendário!$C:$C,C$4) -> 2 | D9: =COUNTIFS(Calendário!$F:$F,$A9,Calendário!$C:$C,D$4) -> 2 | E9: =COUNTIFS(Calendário!$F:$F,$A9,Calendário!$C:$C,E$4) -> 2 | F9: =COUNTIFS(Calendário!$F:$F,$A9,Calendário!$C:$C,F$4) -> 1 | G9: =COUNTIFS(Calendário!$F:$F,$A9,Calendário!$C:$C,G$4) -> 2 | H9: =COUNTIFS(Calendário!$F:$F,$A9,Calendário!$C:$C,H$4) -> 1 | I9: =COUNTIFS(Calendário!$F:$F,$A9,Calendário!$C:$C,I$4) -> 1 | J9: =COUNTIFS(Calendário!$F:$F,$A9,Calendário!$C:$C,J$4) -> 2 | ... L9: =COUNTIFS(Calendário!$F:$F,$A9,Calendário!$C:$C,L$4) -> 2 | M9: =SUM(C9:L9) -> 17
A10: Residencial Fiorello | B10: Quinta | C10: =COUNTIFS(Calendário!$F:$F,$A10,Calendário!$C:$C,C$4) -> 2 | D10: =COUNTIFS(Calendário!$F:$F,$A10,Calendário!$C:$C,D$4) -> 2 | E10: =COUNTIFS(Calendário!$F:$F,$A10,Calendário!$C:$C,E$4) -> 2 | F10: =COUNTIFS(Calendário!$F:$F,$A10,Calendário!$C:$C,F$4) -> 1 | G10: =COUNTIFS(Calendário!$F:$F,$A10,Calendário!$C:$C,G$4) -> 2 | H10: =COUNTIFS(Calendário!$F:$F,$A10,Calendário!$C:$C,H$4) -> 1 | I10: =COUNTIFS(Calendário!$F:$F,$A10,Calendário!$C:$C,I$4) -> 1 | J10: =COUNTIFS(Calendário!$F:$F,$A10,Calendário!$C:$C,J$4) -> 2 | ... L10: =COUNTIFS(Calendário!$F:$F,$A10,Calendário!$C:$C,L$4) -> 2 | M10: =SUM(C10:L10) -> 17
A11: Primado Residence | B11: Sexta | C11: =COUNTIFS(Calendário!$F:$F,$A11,Calendário!$C:$C,C$4) -> 2 | D11: =COUNTIFS(Calendário!$F:$F,$A11,Calendário!$C:$C,D$4) -> 2 | E11: =COUNTIFS(Calendário!$F:$F,$A11,Calendário!$C:$C,E$4) -> 2 | F11: =COUNTIFS(Calendário!$F:$F,$A11,Calendário!$C:$C,F$4) -> 1 | G11: =COUNTIFS(Calendário!$F:$F,$A11,Calendário!$C:$C,G$4) -> 2 | H11: =COUNTIFS(Calendário!$F:$F,$A11,Calendário!$C:$C,H$4) -> 1 | I11: =COUNTIFS(Calendário!$F:$F,$A11,Calendário!$C:$C,I$4) -> 1 | J11: =COUNTIFS(Calendário!$F:$F,$A11,Calendário!$C:$C,J$4) -> 2 | ... L11: =COUNTIFS(Calendário!$F:$F,$A11,Calendário!$C:$C,L$4) -> 2 | M11: =SUM(C11:L11) -> 17
A12: Moradas do Lago | B12: Sexta | C12: =COUNTIFS(Calendário!$F:$F,$A12,Calendário!$C:$C,C$4) -> 2 | D12: =COUNTIFS(Calendário!$F:$F,$A12,Calendário!$C:$C,D$4) -> 2 | E12: =COUNTIFS(Calendário!$F:$F,$A12,Calendário!$C:$C,E$4) -> 2 | F12: =COUNTIFS(Calendário!$F:$F,$A12,Calendário!$C:$C,F$4) -> 1 | G12: =COUNTIFS(Calendário!$F:$F,$A12,Calendário!$C:$C,G$4) -> 2 | H12: =COUNTIFS(Calendário!$F:$F,$A12,Calendário!$C:$C,H$4) -> 1 | I12: =COUNTIFS(Calendário!$F:$F,$A12,Calendário!$C:$C,I$4) -> 1 | J12: =COUNTIFS(Calendário!$F:$F,$A12,Calendário!$C:$C,J$4) -> 2 | ... L12: =COUNTIFS(Calendário!$F:$F,$A12,Calendário!$C:$C,L$4) -> 2 | M12: =SUM(C12:L12) -> 17
A13: Total de peças na semana | C13: =SUM(C5:C12) -> 16 | D13: =SUM(D5:D12) -> 16 | E13: =SUM(E5:E12) -> 16 | F13: =SUM(F5:F12) -> 8 | G13: =SUM(G5:G12) -> 16 | H13: =SUM(H5:H12) -> 8 | I13: =SUM(I5:I12) -> 8 | J13: =SUM(J5:J12) -> 16 | ... L13: =SUM(L5:L12) -> 16 | M13: =SUM(C13:L13) -> 136
A14: · vídeos | C14: =COUNTIFS(Calendário!$C:$C,C$4,Calendário!$G:$G,"Vídeo") -> 5 | D14: =COUNTIFS(Calendário!$C:$C,D$4,Calendário!$G:$G,"Vídeo") -> 6 | E14: =COUNTIFS(Calendário!$C:$C,E$4,Calendário!$G:$G,"Vídeo") -> 5 | F14: =COUNTIFS(Calendário!$C:$C,F$4,Calendário!$G:$G,"Vídeo") -> 4 | G14: =COUNTIFS(Calendário!$C:$C,G$4,Calendário!$G:$G,"Vídeo") -> 4 | H14: =COUNTIFS(Calendário!$C:$C,H$4,Calendário!$G:$G,"Vídeo") -> 4 | I14: =COUNTIFS(Calendário!$C:$C,I$4,Calendário!$G:$G,"Vídeo") -> 4 | J14: =COUNTIFS(Calendário!$C:$C,J$4,Calendário!$G:$G,"Vídeo") -> 5 | ... L14: =COUNTIFS(Calendário!$C:$C,L$4,Calendário!$G:$G,"Vídeo") -> 5 | M14: =SUM(C14:L14) -> 48
A15: · carrosséis | C15: =COUNTIFS(Calendário!$C:$C,C$4,Calendário!$G:$G,"Carrossel") -> 3 | D15: =COUNTIFS(Calendário!$C:$C,D$4,Calendário!$G:$G,"Carrossel") -> 8 | E15: =COUNTIFS(Calendário!$C:$C,E$4,Calendário!$G:$G,"Carrossel") -> 5 | F15: =COUNTIFS(Calendário!$C:$C,F$4,Calendário!$G:$G,"Carrossel") -> 4 | G15: =COUNTIFS(Calendário!$C:$C,G$4,Calendário!$G:$G,"Carrossel") -> 4 | H15: =COUNTIFS(Calendário!$C:$C,H$4,Calendário!$G:$G,"Carrossel") -> 4 | I15: =COUNTIFS(Calendário!$C:$C,I$4,Calendário!$G:$G,"Carrossel") -> 4 | J15: =COUNTIFS(Calendário!$C:$C,J$4,Calendário!$G:$G,"Carrossel") -> 3 | ... L15: =COUNTIFS(Calendário!$C:$C,L$4,Calendário!$G:$G,"Carrossel") -> 5 | M15: =SUM(C15:L15) -> 48
A16: · estáticos | C16: =COUNTIFS(Calendário!$C:$C,C$4,Calendário!$G:$G,"Estático") -> 8 | D16: =COUNTIFS(Calendário!$C:$C,D$4,Calendário!$G:$G,"Estático") -> 2 | E16: =COUNTIFS(Calendário!$C:$C,E$4,Calendário!$G:$G,"Estático") -> 6 | F16: =COUNTIFS(Calendário!$C:$C,F$4,Calendário!$G:$G,"Estático") -> 0 | G16: =COUNTIFS(Calendário!$C:$C,G$4,Calendário!$G:$G,"Estático") -> 8 | H16: =COUNTIFS(Calendário!$C:$C,H$4,Calendário!$G:$G,"Estático") -> 0 | I16: =COUNTIFS(Calendário!$C:$C,I$4,Calendário!$G:$G,"Estático") -> 0 | J16: =COUNTIFS(Calendário!$C:$C,J$4,Calendário!$G:$G,"Estático") -> 8 | ... L16: =COUNTIFS(Calendário!$C:$C,L$4,Calendário!$G:$G,"Estático") -> 6 | M16: =SUM(C16:L16) -> 40

Sheet Posicionamento
A1: POSICIONAMENTO POR EMPREENDIMENTO — base para as chamadas
A3: Empreendimento | B3: Produto / localização | C3: Argumentos-chave | D3: Condição comercial | E3: Tom de comunicação | F3: Público principal | G3: CTA padrão | H3: Validar antes de publicar
A4: Residencial Mont'Santo | B4: Santa Maria · Av. Medianeira · alto padrão · apartamentos de 124 a 245 m² | C4: Obra a preço de custo; m² mais em conta da cidade no verdadeiro alto padrão; localização premium; entrega em 20 meses | D4: Obra a preço de custo (detalhar condição com a construtora) | E4: Sofisticado e direto, com argumento racional (preço/m²) | F4: Famílias e investidores de alto padrão de Santa Maria | G4: Fale com um consultor no WhatsApp | H4: Confirmar como comunicar 'preço de custo' (regras da SPE) e o prazo de 20 meses
A5: Sync Floriano | B5: Santa Maria · próximo ao Hospital de Caridade · studio, 1 e 2 dormitórios · obra em SPE | C5: Localização estratégica; condição flexível; tipologias compactas; segurança da SPE | D5: Até 40 meses; entrada de 10% ou a partir de R$ 10 mil; parcelas na faixa de R$ 1 mil (SUGESTÃO) | E5: Próximo e prático, focado em condição | F5: 1º imóvel, profissionais da saúde, estudantes e investidores de aluguel | G5: Simule sua condição no WhatsApp | H5: Validar com a construtora a condição sugerida (entrada R$ 10 mil / parcelas ~R$ 1 mil) e o nome da construtora antes de publicar
A6: Residencial Einstein | B6: Muito próximo da entrega | C6: Quase pronto; várias formas de pagamento | D6: 20% durante a obra e saldo financiado nas chaves; aceita permuta; aceita Plano Safra | E6: Consultivo, mostrando possibilidades | F6: Famílias, produtores rurais, quem tem bem para dar na troca | G6: Fale com um consultor no WhatsApp | H6: Validar regras do Plano Safra para a compra, que bens entram na permuta e as unidades livres (há negociação de várias unidades em andamento)
A7: Infinity Residence | B7: Altíssimo padrão · um dos maiores empreendimentos do centro do estado | C7: Exclusividade, localização, produto único | D7: NÃO comunicar condição nem preço | E7: Aspiracional, minimalista, cinematográfico | F7: Alta renda, empresários, quem busca um imóvel único | G7: Agende uma apresentação privada | H7: Confirmar nomes de parceiros do projeto antes do carrossel 'Assinaturas'
A8: Residencial Amália | B8: Próximo à UFSM · entrega no início do ano | C8: Localização perto da universidade; entrega no início do ano letivo; demanda de aluguel | D8: Fluxo direto com a construtora ou financiamento | E8: Informativo, falando com pais e investidores | F8: Pais de universitários, estudantes, investidores | G8: Fale com um consultor no WhatsApp | H8: Confirmar mês de entrega e as condições do fluxo direto
A9: Residencial Fiorello | B9: Pronto · 2 apartamentos tipo e a cobertura disponíveis | C9: Exclusividade, produto único, pronto para morar, escassez real | D9: Aceita até 50% em permuta | E9: Elegante e com urgência | F9: Alta renda, quem tem imóvel para dar na troca | G9: Agende sua visita | H9: Atualizar as peças de estoque (2 apartamentos tipo e a cobertura) assim que alguma unidade for vendida
A10: Primado Residence | B10: Lotes · 7 min do Recanto Maestro · região da 4ª Colônia | C10: Polo turístico o ano todo; infraestrutura 95% concluída; qualidade de vida | D10: Detalhar com a construtora (tamanhos e condição dos lotes) | E10: Inspirador, natureza e investimento | F10: Investidores, quem quer casa de campo/temporada, moradores da região | G10: Fale com um consultor no WhatsApp | H10: Confirmar tamanhos de lote, condição de pagamento e o percentual de 95%
A11: Moradas do Lago | B11: Lajeado · apartamentos prontos | C11: Pronto para morar; facilidade de compra | D11: Financiamento de até 100% pelo Banrisul; fluxo direto com a construtora; análise de permuta | E11: Acolhedor e prático | F11: Famílias e 1º imóvel em Lajeado | G11: Simule seu financiamento no WhatsApp | H11: Validar uso do nome/marca Banrisul nas peças e as regras do financiamento 100%

Sheet Premissas
A1: PREMISSAS E REGRAS
A3: Parâmetro | B3: Valor | D3: Feriados considerados | E3: Data
A4: Prazo de aprovação (dias úteis antes de subir) | B4: 2
D5: N. Sra. Aparecida | E5: 46307
D6: Finados | E6: 46328
D7: Proclamação da República | E7: 46341
D8: Consciência Negra | E8: 46346
D9: N. Sra. da Conceição (ver local) | E9: 46364
D10: Natal | E10: 46381
D11: Confraternização | E11: 46388
A14: COMO USAR
A15: • Aba Calendário: lista completa de criativos com data, ideia e chamada. Atualize a coluna Status (lista suspensa) e o Responsável.
A16: • Resumo mensal e Fluxo semanal se atualizam sozinhos a partir do Calendário.
A17: • 'Aprovação até' = data de subida menos o prazo acima (dias úteis). Altere o prazo na célula amarela.
A18: • Outubro começa na semana de 12/10 (primeira entrega de aprovação em 08/10).
A20: LÓGICA DO MIX (por projeto)
A21: • Outubro: 2 vídeos · 2 carrosséis · 2 estáticos = 6 → apresentar o principal argumento de cada empreendimento.
A22: • Novembro: 2 vídeos · 2 carrosséis · 1 estático = 5 → aprofundar produto, condição e prova; escalar o que performou em outubro.
A23: • Dezembro: 2 vídeos · 2 carrosséis · 2 estáticos = 6 → oferta de fim de ano, urgência e 'comece 2027'.
A24: • Vídeos: Reels/Stories 9:16 (15–30s) + versão 4:5 para feed. Carrossel: 3 a 6 cards. Estático: 1:1 ou 4:5.
A26: REGRAS DE GESTÃO
A27: • Criativos vencedores continuam no ar; os números do calendário são só peças NOVAS.
... A31: • Chamadas com valores (Sync, Einstein, Moradas) só sobem depois de validadas com a construtora — ver coluna Observações.
